Workbook

Sheet old1前年変更タスク一覧
B1: Eng. | C1: 大カテゴリ | D1: 中カテゴリ | E1: タスク名 | F1: 恒久工数 | G1: 一時工数 | H1: FY27工数 | I1: 増減 | J1: 増減 | K1: 増減理由
B2: {=_xlfn.HSTACK(_xlfn._xlws.FILTER(FY27工数!A2:E1011, FY27工数!K2:K1011<>""), _xlfn._xlws.FILTER(FY27工数!G2:I1011, FY27工数!K2:K1011<>""), _xlfn._xlws.FILTER(FY27工数!K2:L1011, FY27工数!K2:K1011<>""), _xlfn._xlws.FILTER(FY27工数!Q2:Q1011, FY27工数!K2:K1011<>""))} -> FFG | C2: ITGC | D2: WT | E2: B90C1 | F2: MC束ね(不動産・人事・Siatol・国際・収益・財務・時価・固定資産) | G2: 18 | H2: 1 | I2: 19 | J2: 内訳変更 | L2: 人事情報束ね分離
B3: FFG | C3: ITGC | D3: TOC | E3: B90C1 | F3: MC束ね(不動産・人事・Siatol・国際・収益・財務・時価・固定資産) | G3: 20 | H3: 1 | I3: 21 | J3: 内訳変更 | L3: 人事情報束ね分離
B4: FFG | C4: ITGC | D4: WT | E4: 0 | F4: Siatol MC | G4: 7 | H4: 3 | I4: 10 | J4: 追加 | K4: 10 | L4: FY27 Siatolのクラウド更改
B5: FFG | C5: ITGC | D5: WT | E5: 0 | F5: Siatol MO | G5: 6 | H5: 2 | I5: 8 | J5: 追加 | K5: 8 | L5: FY27 Siatolのクラウド更改
B6: FFG | C6: ITGC | D6: WT | E6: 0 | F6: MA(不動産・人事・Siatol・財務・時価) | G6: 18 | H6: 2 | I6: 20 | J6: 変更 | K6: 1 | L6: 人事情報束ね分離
B7: FFG | C7: ITGC | D7: TOC | E7: 0 | F7: MA(不動産・人事・Siatol・財務・時価) | G7: 20 | H7: 3 | I7: 23 | J7: 変更 | K7: 2 | L7: 人事情報束ね分離
B8: FFG | C8: ITGC | D8: WT | E8: B90G3, B90G4 | F8: Siatol(MAアプリ、MAインフラ) | G8: 10 | H8: 10 | I8: 20 | J8: 変更 | K8: 10 | L8: FY27 Siatolのクラウド更改
B9: FFG | C9: ITGC | D9: TOC | E9: B90G3, B90G4 | F9: Siatol(MAアプリ、MAインフラ) | G9: 0 | H9: 0 | I9: 0 | J9: 削除 | K9: -11 | L9: FY27 Siatolのクラウド更改
B10: FFG | C10: ITGC | D10: RF | E10: B90G3, B90G4 | F10: Siatol(MAアプリ、MAインフラ) | G10: 0 | H10: 0 | I10: 0 | J10: 削除 | K10: -4 | L10: FY27 Siatolのクラウド更改
B11: FFG | C11: ITGC | D11: WT | E11: B90E6 | F11: MO束ね(本部決裁・不動産・人事・時価・固定・FFG勘定奉行) | G11: 13 | H11: 1 | I11: 14 | J11: 変更 | K11: 1 | L11: 人事情報束ね分離
B12: FFG | C12: ITGC | D12: TOC | E12: B90E6 | F12: MO束ね(本部決裁・不動産・人事・時価・固定・FFG勘定奉行) | G12: 14 | H12: 1 | I12: 15 | J12: 変更 | K12: 1 | L12: 人事情報束ね分離
B13: FFG | C13: ITGC | D13: WT | E13: B9181, B9183, B9186 | F13: honorJS | G13: 17 | H13: 0 | I13: 17 | J13: 変更 | K13: -17 | L13: FY26のFCB対応終了
B14: FFG | C14: ITGC | D14: WT | E14: B9259 | F14: RPA | G14: 17 | H14: 0 | I14: 17 | J14: 変更 | K14: -17 | L14: FY26統制整備完了のため減少
B15: FFG | C15: ITGC | D15: TOC | E15: B9259 | F15: RPA | G15: 25.5 | H15: 0 | I15: 25.5 | J15: 追加 | K15: 25.5 | L15: FY27TOC新規実施のため追加
B16: FFG | C16: ITGC | D16: RF | E16: B9259 | F16: RPA | G16: 7.5 | H16: 0 | I16: 7.5 | J16: 追加 | K16: 7.5 | L16: FY27RF新規実施のため追加
B17: FFG | C17: ITGC | D17: WT | E17: 0 | F17: FFGクラウド(AWS) 束ね | G17: 24 | H17: 0 | I17: 24 | J17: 変更 | K17: 14 | L17: FY26の想定よりFY27統制数増加のため追加
B18: FFG | C18: ITGC | D18: TOC | E18: 0 | F18: FFGクラウド(AWS) 束ね | G18: 16 | H18: 0 | I18: 16 | J18: 変更 | K18: 6 | L18: FY26の想定よりFY27統制数増加のため追加
B19: FFG | C19: ITGC | D19: RF | E19: 0 | F19: FFGクラウド(AWS) 束ね | G19: 16 | H19: 0 | I19: 16 | J19: 変更 | K19: 11 | L19: FY26の想定よりFY27統制数増加のため追加
B20: FFG | C20: ITGC | D20: WT | E20: 0 | F20: (旧) 人事情報システム(MC, MA, MO) | G20: 0 | H20: 32 | I20: 32 | J20: 追加 | K20: 32 | L20: 2026年8月にクラウド(COMPANY)更改
B21: FFG | C21: ITGC | D21: WT | E21: 0 | F21: (新)人事情報システム(相補的) | G21: 9 | H21: 9 | I21: 18 | J21: 追加 | K21: 18 | L21: 2026年8月にクラウド(COMPANY)更改
B22: FFG | C22: ITGC | D22: TOC | E22: 0 | F22: (新)人事情報システム(相補的) | G22: 9 | H22: 9 | I22: 18 | J22: 追加 | K22: 18 | L22: 2026年8月にクラウド(COMPANY)更改
B23: FFG | C23: ITGC | D23: RF | E23: 0 | F23: (新)人事情報システム(相補的) | G23: 4 | H23: 4 | I23: 8 | J23: 追加 | K23: 8 | L23: 2026年8月にクラウド(COMPANY)更改
B24: FFG | C24: ITGC | D24: WT | E24: 0 | F24: (新)人事情報システム(MA) | G24: 9 | H24: 9 | I24: 18 | J24: 追加 | K24: 18 | L24: 2026年8月にクラウド(COMPANY)更改
B25: FFG | C25: ITGC | D25: TOC | E25: 0 | F25: (新)人事情報システム(MA) | G25: 9 | H25: 9 | I25: 18 | J25: 追加 | K25: 18 | L25: 2026年8月にクラウド(COMPANY)更改
B26: FFG | C26: ITGC | D26: RF | E26: 0 | F26: (新)人事情報システム(MA) | G26: 4 | H26: 4 | I26: 8 | J26: 追加 | K26: 8 | L26: 2026年8月にクラウド(COMPANY)更改
B27: FFG | C27: ITGC | D27: WT | E27: 0 | F27: (新)人事情報システム(SOC) | G27: 1 | H27: 9 | I27: 10 | J27: 追加 | K27: 10 | L27: 2026年8月にクラウド(COMPANY)更改
B28: FFG | C28: ITGC | D28: RF | E28: 0 | F28: (新)人事情報システム(SOC) | G28: 9 | H28: 2 | I28: 11 | J28: 追加 | K28: 11 | L28: 2026年8月にクラウド(COMPANY)更改
... B37: FFG | C37: ITGC | D37: RF | E37: 0 | F37: 資金証券(Siatol~NE, FM)新プロセス評価 | G37: 0 | H37: 0 | I37: 0 | J37: 削除 | K37: -5 | L37: FY26限定トピック
B38: FFG | C38: ITGC | D38: WT | E38: B9xxx | F38: 特権ID管理システム(iOperation) | G38: 17 | H38: 0 | I38: 17 | J38: 追加 | K38: 17 | L38: FY27からタスクとして独立
B39: FFG | C39: ITGC | D39: TOC | E39: B9xxx | F39: 特権ID管理システム(iOperation) | G39: 17 | H39: 0 | I39: 17 | J39: 追加 | K39: 17 | L39: FY27からタスクとして独立
B40: FFG | C40: ITGC | D40: RF | E40: B9xxx | F40: 特権ID管理システム(iOperation) | G40: 5 | H40: 0 | I40: 5 | J40: 追加 | K40: 5 | L40: FY27からタスクとして独立
B41: FFG | C41: ITGC | D41: WT | E41: B9xxx | F41: 特権ID管理システム(AccessCheck) | G41: 17 | H41: 0 | I41: 17 | J41: 追加 | K41: 17 | L41: FY27からタスクとして独立
B42: FFG | C42: ITGC | D42: TOC | E42: B9xxx | F42: 特権ID管理システム(AccessCheck) | G42: 17 | H42: 0 | I42: 17 | J42: 追加 | K42: 17 | L42: FY27からタスクとして独立
B43: FFG | C43: ITGC | D43: RF | E43: B9xxx | F43: 特権ID管理システム(AccessCheck) | G43: 5 | H43: 0 | I43: 5 | J43: 追加 | K43: 5 | L43: FY27からタスクとして独立
B44: FFG | C44: 個別工数 | D44: WT | E44: 0 | F44: AWS基盤の調書束ね | G44: 16 | H44: 0 | I44: 16 | J44: 変更 | K44: -24 | L44: FY27は工数削減のうえ、個別システムの特性見直し
B45: FFG | C45: 個別工数 | D45: WT | E45: 0 | F45: EYJP265の調書フォーマット変更 | G45: 0 | H45: 22 | I45: 22 | J45: 追加 | K45: 22 | L45: FY27のトピック
B46: FFG | C46: 個別工数 | D46: その他 | E46: 0 | F46: 融資支援RCM再検討 | G46: 0 | H46: 0 | I46: 0 | J46: 削除 | K46: -24 | L46: J-SOX実施可能性がなくなったため、削除
B47: FFG | C47: 個別工数 | D47: WT | E47: B9007 | F47: サイバーリスク評価 | G47: 20 | H47: 0 | I47: 20 | J47: 変更 | K47: -32 | L47: 工数の適正化
B48: FFG | C48: 個別工数 | D48: TOC | E48: B9007 | F48: サイバーリスク評価 | G48: 20 | H48: 0 | I48: 20 | J48: 変更 | K48: -32 | L48: 工数の適正化

Sheet 全タスク集計
A3: 行ラベル | B3: 合計 / FY27工数
A4: ITGC | B4: 1244
A5: (FFG) 勘定奉行＊ | B5: 16
A6: (FFG) 連結納税＊ | B6: 17
A7: (FFG)リスク管理高度化 | B7: 7
A8: BancMeasure+ | B8: 7
A9: BESTWAY | B9: 3
A10: FFGカード関連外部サービス | B10: 3
A11: FFGクラウド(AWS) 束ね | B11: 56
A12: honorJS | B12: 39
A13: MA(不動産・人事・Siatol・財務・時価) | B13: 50
A14: MC束ね(不動産・人事・Siatol・国際・収益・財務・時価・固定資産) | B14: 47
A15: MC束ね(本部決裁・個人ローン・投資経費) | B15: 46
... A113: 総計 | B113: 1799

Sheet 前期差分集計
B1: FY27 | E1: FY26
A2: タスク名 | B2: 恒久工数 | C2: 一時工数 | D2: 工数 | E2: 恒久工数 | F2: 一時工数 | G2: 工数 | H2: 増減ステータス | I2: 工数差分 | J2: 増減理由
A3: {=_xlfn.LET( _xlpm.集計表, _xlfn.HSTACK( _xlfn.GROUPBY(_xlfn.HSTACK(T_FY27[タスクID], T_FY27[タスク名]), _xlfn.HSTACK(T_FY27[恒久工数], T_FY27[一時工数], T_FY27[FY27工数], T_FY27[工数差分]), _xleta.SUM, 0, 0), _xlfn.CHOOSECOLS(_xlfn.GROUPBY(_xlfn.HSTACK(T_FY27[タスクID], T_FY27[タスク名]), _xlfn.HSTACK(T_FY27[増減], T_FY27[増減理由]), _xleta.ARRAYTOTEXT, 0, 0), 3, 4) ), _xlpm.絞り込み, _xlfn._xlws.FILTER(_xlpm.集計表, (INDEX(_xlpm.集計表,,6)<>0) + ISNUMBER(SEARCH("内訳変更", INDEX(_xlpm.集計表,,7)))), _xlpm.タスク名リスト, INDEX(_xlpm.絞り込み,,2), _xlpm.FY26恒久, SUMIFS(T_FY26[恒久工数], T_FY26[タスク名], _xlpm.タスク名リスト), _xlpm.FY26一時, SUMIFS(T_FY26[一時工数], T_FY26[タスク名], _xlpm.タスク名リスト), _xlpm.FY26工数, SUMIFS(T_FY26[FY26工数], T_FY26[タスク名], _xlpm.タスク名リスト), _xlpm.結果表, _xlfn.HSTACK(_xlpm.絞り込み, _xlpm.FY26恒久, _xlpm.FY26一時, _xlpm.FY26工数), _xlfn.CHOOSECOLS(_xlpm.結果表, 2, 3, 4, 5, 9, 10, 11, 7, 6, 8) )} -> サイバーリスク評価 | B3: 50 | C3: 0 | D3: 50 | E3: 114 | F3: 0 | G3: 114 | H3: 変更, 変更, | I3: -64 | J3: 工数の適正化, 工数の適正化,
A4: MC束ね(不動産・人事・Siatol・国際・収益・財務・時価・固定資産) | B4: 45 | C4: 2 | D4: 47 | E4: 47 | F4: 0 | G4: 47 | H4: 内訳変更, 内訳変更, | I4: 0 | J4: 人事情報束ね分離, 人事情報束ね分離,
A5: MO束ね(本部決裁・不動産・人事・時価・固定・FFG勘定奉行) | B5: 33 | C5: 2 | D5: 35 | E5: 33 | F5: 0 | G5: 33 | H5: 変更, 変更, | I5: 2 | J5: 人事情報束ね分離, 人事情報束ね分離, 人事情報束ね分離
A6: Siatol(MAアプリ、MAインフラ) | B6: 10 | C6: 10 | D6: 20 | E6: 25 | F6: 0 | G6: 25 | H6: 変更, 削除, 削除 | I6: -5 | J6: FY27 Siatolのクラウド更改, FY27 Siatolのクラウド更改, FY27 Siatolのクラウド更改
A7: honorJS | B7: 39 | C7: 0 | D7: 39 | E7: 56 | F7: 0 | G7: 56 | H7: 変更, , | I7: -17 | J7: FY26のFCB対応終了, ,
A8: RPA | B8: 50 | C8: 0 | D8: 50 | E8: 34 | F8: 0 | G8: 34 | H8: 変更, 追加, 追加 | I8: 16 | J8: FY26統制整備完了のため減少, FY27TOC新規実施のため追加, FY27RF新規実施のため追加
A9: 特権ID管理システム(AccessCheck) | B9: 39 | C9: 0 | D9: 39 | E9: 0 | F9: 0 | G9: 0 | H9: 追加, 追加, 追加 | I9: 39 | J9: FY27からタスクとして独立, FY27からタスクとして独立, FY27からタスクとして独立
A10: 特権ID管理システム(iOperation) | B10: 39 | C10: 0 | D10: 39 | E10: 0 | F10: 0 | G10: 0 | H10: 追加, 追加, 追加 | I10: 39 | J10: FY27からタスクとして独立, FY27からタスクとして独立, FY27からタスクとして独立
A11: (旧) 人事情報システム(MC, MA, MO) | B11: 0 | C11: 32 | D11: 32 | E11: 0 | F11: 0 | G11: 0 | H11: 追加 | I11: 32 | J11: 2026年8月にクラウド(COMPANY)更改
A12: (新)人事情報システム(MA) | B12: 22 | C12: 22 | D12: 44 | E12: 0 | F12: 0 | G12: 0 | H12: 追加, 追加, 追加 | I12: 44 | J12: 2026年8月にクラウド(COMPANY)更改, 2026年8月にクラウド(COMPANY)更改, 2026年8月にクラウド(COMPANY)更改
A13: (新)人事情報システム(SOC) | B13: 10 | C13: 11 | D13: 21 | E13: 0 | F13: 0 | G13: 0 | H13: 追加, 追加 | I13: 21 | J13: 2026年8月にクラウド(COMPANY)更改, 2026年8月にクラウド(COMPANY)更改
A14: (新)人事情報システム(相補的) | B14: 22 | C14: 22 | D14: 44 | E14: 0 | F14: 0 | G14: 0 | H14: 追加, 追加, 追加 | I14: 44 | J14: 2026年8月にクラウド(COMPANY)更改, 2026年8月にクラウド(COMPANY)更改, 2026年8月にクラウド(COMPANY)更改
A15: AWS基盤の調書束ね | B15: 16 | C15: 0 | D15: 16 | E15: 40 | F15: 0 | G15: 40 | H15: 変更 | I15: -24 | J15: FY27は工数削減のうえ、個別システムの特性見直し
... A28: 融資支援RCM再検討 | B28: 0 | C28: 0 | D28: 0 | E28: 24 | F28: 0 | G28: 24 | H28: 削除 | I28: -24 | J28: J-SOX実施可能性がなくなったため、削除

Sheet 月別集計
A1: 実施月 | B1: 月ごと総工数
A2: {=_xlfn.LET( _xlpm.月順, {7;8;9;10;11;12;1;2;3;4;5;6}, _xlpm.集計結果, _xlfn.GROUPBY(T_FY27[実施月], T_FY27[FY27工数], _xleta.SUM, 0, 0, , T_FY27[実施月]<>""), _xlfn.SORTBY(_xlpm.集計結果, MATCH(INDEX(_xlpm.集計結果,,1), _xlpm.月順, 0)) )} -> 7 | B2: 19
A3: 8 | B3: 67
A4: 9 | B4: 569
A5: 10 | B5: 253
A6: 11 | B6: 33
A7: 12 | B7: 16
A8: 2 | B8: 466.5
A9: 3 | B9: 49
A10: 4 | B10: 223.5
A11: 6 | B11: 103
A12: - | B12: 0

Sheet 個人別集計
A1: {=_xlfn.LET( _xlpm.総工数, T_FY27[FY27工数], _xlpm.担1, T_FY27[担当1], _xlpm.担2, T_FY27[担当2], _xlpm.担3, T_FY27[担当3], _xlpm.人数, (_xlpm.担1<>"") + (_xlpm.担2<>"") + (_xlpm.担3<>""), _xlpm.安全人数, IF(_xlpm.人数=0, 1, _xlpm.人数), _xlpm.ベース, INT(_xlpm.総工数 / _xlpm.安全人数), _xlpm.余り, MOD(_xlpm.総工数, _xlpm.安全人数), _xlpm.工数1, IF(_xlpm.担1<>"", _xlpm.ベース + (_xlpm.余り>=1), 0), _xlpm.工数2, IF(_xlpm.担2<>"", _xlpm.ベース + (_xlpm.余り>=2), 0), _xlpm.工数3, IF(_xlpm.担3<>"", _xlpm.ベース, 0), _xlpm.全名前, _xlfn.VSTACK(_xlpm.担1, _xlpm.担2, _xlpm.担3), _xlpm.全工数, _xlfn.VSTACK(_xlpm.工数1, _xlpm.工数2, _xlpm.工数3), _xlpm.集計, _xlfn.GROUPBY(_xlpm.全名前, _xlpm.全工数, _xleta.SUM, 0, 0, , (_xlpm.全名前<>"")*(_xlpm.全名前<>0)), _xlfn.VSTACK({"担当者","分配後工数"}, _xlpm.集計) )} -> 担当者 | B1: 分配後工数
A2: A | B2: 14
A3: B | B3: 14
A4: C | B4: 13

Sheet 前年変更タスク(lambda)
A1: {=_xlfn.HSTACK( _xlfn.GROUPBY(FY27工数!E2:E1011, FY27工数!G2:I1011, _xleta.SUM, 0, 0, , FY27工数!K2:K1011<>""), _xlfn.CHOOSECOLS(_xlfn.GROUPBY(FY27工数!E2:E1011, FY27工数!Q2:Q1011, LAMBDA(x, _xlfn.ARRAYTOTEXT(_xlfn.UNIQUE(x))), 0, 0, , FY27工数!K2:K1011<>""), 2) )} -> #NAME?

Sheet 担当分担表集計
A1: {=_xlfn.LET( _xlpm.担1, T_FY27[担当1]&"", _xlpm.担2, T_FY27[担当2]&"", _xlpm.担3, T_FY27[担当3]&"", _xlpm.担当まとめ, _xlpm.担1 & IF(_xlpm.担2<>"", ", "&_xlpm.担2, "") & IF(_xlpm.担3<>"", ", "&_xlpm.担3, ""), _xlfn.PIVOTBY(T_FY27[タスク名], T_FY27[中カテゴリ], _xlpm.担当まとめ, _xleta.ARRAYTOTEXT, 3, 0, , 0, , T_FY27[大カテゴリ]="ITGC") )} | B1: WT
B2: 315対応 | C2: RF | D2: TOC | E2: WT | F2: 移行
A3: 勘定系 | B3: A, B, C | C3: A, B, C | D3: A, B, C | E3: A, B, C | F3: A, B, C
A4: (FFG) 勘定奉行＊
A5: (FFG) 連結納税＊
A6: (FFG)リスク管理高度化
A7: (旧) 人事情報システム(MC, MA, MO)
A8: (新)人事情報システム(MA)
A9: (新)人事情報システム(SOC)
A10: (新)人事情報システム(相補的)
A11: BancMeasure+
A12: BESTWAY
A13: FFGカード関連外部サービス
A14: FFGクラウド(AWS) 束ね
A15: honorJS
... A55: 融資支援(MO束ね)

Sheet FY27工数
A1: Eng. | B1: 大カテゴリ | C1: 中カテゴリ | D1: タスクID | E1: タスク名 | F1: (作業用)タスク結合名 | G1: 恒久工数 | H1: 一時工数 | I1: FY27工数 | J1: FY26工数 | K1: 増減 | L1: 工数差分 | M1: 実施月 | N1: 担当1 | O1: 担当2 | P1: 担当3 | Q1: 増減理由 | R1: 見積根拠
A2: FFG | B2: ITGC | C2: WT | D2: B9011, B9014, B9015, B9016 | E2: 勘定系 | F2: =T_FY27[[#This Row],[Eng.]]&T_FY27[[#This Row],[大カテゴリ]]&T_FY27[[#This Row],[中カテゴリ]]&T_FY27[[#This Row],[タスク名]] -> FFGITGCWT勘定系 | G2: 41 | I2: =SUM(T_FY27[[#This Row],[恒久工数]:[一時工数]]) -> 41 | J2: =_xlfn.XLOOKUP(T_FY27[[#This Row],[(作業用)タスク結合名]],FY26工数!$F:$F,FY26工数!$I:$I,0) -> 41 | K2: =_xlfn.LET( _xlpm.FY26恒久, _xlfn.XLOOKUP(T_FY27[[#This Row],[(作業用)タスク結合名]], T_FY26[(作業用)タスク結合名], T_FY26[恒久工数], 0), _xlpm.FY26一時, _xlfn.XLOOKUP(T_FY27[[#This Row],[(作業用)タスク結合名]], T_FY26[(作業用)タスク結合名], T_FY26[一時工数], 0), IF(T_FY27[[#This Row],[FY27工数]]<>T_FY27[[#This Row],[FY26工数]], IF(T_FY27[[#This Row],[FY26工数]]=0, "追加", IF(T_FY27[[#This Row],[FY27工数]]=0, "削除", "変更")), IF(OR(T_FY27[[#This Row],[恒久工数]]<>_xlpm.FY26恒久, T_FY27[[#This Row],[一時工数]]<>_xlpm.FY26一時), "内訳変更", "") ) ) | L2: =IF(T_FY27[[#This Row],[FY27工数]]=T_FY27[[#This Row],[FY26工数]], "", T_FY27[[#This Row],[FY27工数]]-T_FY27[[#This Row],[FY26工数]]) | M2: 9 | N2: A | O2: B | P2: C
A3: FFG | B3: ITGC | C3: TOC | D3: B9011, B9014, B9015, B9016 | E3: 勘定系 | F3: =T_FY27[[#This Row],[Eng.]]&T_FY27[[#This Row],[大カテゴリ]]&T_FY27[[#This Row],[中カテゴリ]]&T_FY27[[#This Row],[タスク名]] -> FFGITGCTOC勘定系 | G3: 45 | I3: =SUM(T_FY27[[#This Row],[恒久工数]:[一時工数]]) -> 45 | J3: =_xlfn.XLOOKUP(T_FY27[[#This Row],[(作業用)タスク結合名]],FY26工数!$F:$F,FY26工数!$I:$I,0) -> 45 | K3: =_xlfn.LET( _xlpm.FY26恒久, _xlfn.XLOOKUP(T_FY27[[#This Row],[(作業用)タスク結合名]], T_FY26[(作業用)タスク結合名], T_FY26[恒久工数], 0), _xlpm.FY26一時, _xlfn.XLOOKUP(T_FY27[[#This Row],[(作業用)タスク結合名]], T_FY26[(作業用)タスク結合名], T_FY26[一時工数], 0), IF(T_FY27[[#This Row],[FY27工数]]<>T_FY27[[#This Row],[FY26工数]], IF(T_FY27[[#This Row],[FY26工数]]=0, "追加", IF(T_FY27[[#This Row],[FY27工数]]=0, "削除", "変更")), IF(OR(T_FY27[[#This Row],[恒久工数]]<>_xlpm.FY26恒久, T_FY27[[#This Row],[一時工数]]<>_xlpm.FY26一時), "内訳変更", "") ) ) | L3: =IF(T_FY27[[#This Row],[FY27工数]]=T_FY27[[#This Row],[FY26工数]], "", T_FY27[[#This Row],[FY27工数]]-T_FY27[[#This Row],[FY26工数]]) | M3: 2
A4: FFG | B4: ITGC | C4: RF | D4: B9011, B9014, B9015, B9016 | E4: 勘定系 | F4: =T_FY27[[#This Row],[Eng.]]&T_FY27[[#This Row],[大カテゴリ]]&T_FY27[[#This Row],[中カテゴリ]]&T_FY27[[#This Row],[タスク名]] -> FFGITGCRF勘定系 | G4: 11 | I4: =SUM(T_FY27[[#This Row],[恒久工数]:[一時工数]]) -> 11 | J4: =_xlfn.XLOOKUP(T_FY27[[#This Row],[(作業用)タスク結合名]],FY26工数!$F:$F,FY26工数!$I:$I,0) -> 11 | K4: =_xlfn.LET( _xlpm.FY26恒久, _xlfn.XLOOKUP(T_FY27[[#This Row],[(作業用)タスク結合名]], T_FY26[(作業用)タスク結合名], T_FY26[恒久工数], 0), _xlpm.FY26一時, _xlfn.XLOOKUP(T_FY27[[#This Row],[(作業用)タスク結合名]], T_FY26[(作業用)タスク結合名], T_FY26[一時工数], 0), IF(T_FY27[[#This Row],[FY27工数]]<>T_FY27[[#This Row],[FY26工数]], IF(T_FY27[[#This Row],[FY26工数]]=0, "追加", IF(T_FY27[[#This Row],[FY27工数]]=0, "削除", "変更")), IF(OR(T_FY27[[#This Row],[恒久工数]]<>_xlpm.FY26恒久, T_FY27[[#This Row],[一時工数]]<>_xlpm.FY26一時), "内訳変更", "") ) ) | L4: =IF(T_FY27[[#This Row],[FY27工数]]=T_FY27[[#This Row],[FY26工数]], "", T_FY27[[#This Row],[FY27工数]]-T_FY27[[#This Row],[FY26工数]]) | M4: 4
A5: FFG | B5: ITGC | C5: WT | D5: B90A2 | E5: 勘定系・融資支援(MCインフラ束ね) | F5: =T_FY27[[#This Row],[Eng.]]&T_FY27[[#This Row],[大カテゴリ]]&T_FY27[[#This Row],[中カテゴリ]]&T_FY27[[#This Row],[タスク名]] -> FFGITGCWT勘定系・融資支援(MCインフラ束ね) | G5: 10 | I5: =SUM(T_FY27[[#This Row],[恒久工数]:[一時工数]]) -> 10 | J5: =_xlfn.XLOOKUP(T_FY27[[#This Row],[(作業用)タスク結合名]],FY26工数!$F:$F,FY26工数!$I:$I,0) -> 10 | K5: =_xlfn.LET( _xlpm.FY26恒久, _xlfn.XLOOKUP(T_FY27[[#This Row],[(作業用)タスク結合名]], T_FY26[(作業用)タスク結合名], T_FY26[恒久工数], 0), _xlpm.FY26一時, _xlfn.XLOOKUP(T_FY27[[#This Row],[(作業用)タスク結合名]], T_FY26[(作業用)タスク結合名], T_FY26[一時工数], 0), IF(T_FY27[[#This Row],[FY27工数]]<>T_FY27[[#This Row],[FY26工数]], IF(T_FY27[[#This Row],[FY26工数]]=0, "追加", IF(T_FY27[[#This Row],[FY27工数]]=0, "削除", "変更")), IF(OR(T_FY27[[#This Row],[恒久工数]]<>_xlpm.FY26恒久, T_FY27[[#This Row],[一時工数]]<>_xlpm.FY26一時), "内訳変更", "") ) ) | L5: =IF(T_FY27[[#This Row],[FY27工数]]=T_FY27[[#This Row],[FY26工数]], "", T_FY27[[#This Row],[FY27工数]]-T_FY27[[#This Row],[FY26工数]]) | M5: 9
A6: FFG | B6: ITGC | C6: TOC | D6: B90A2 | E6: 勘定系・融資支援(MCインフラ束ね) | F6: =T_FY27[[#This Row],[Eng.]]&T_FY27[[#This Row],[大カテゴリ]]&T_FY27[[#This Row],[中カテゴリ]]&T_FY27[[#This Row],[タスク名]] -> FFGITGCTOC勘定系・融資支援(MCインフラ束ね) | G6: 12 | I6: =SUM(T_FY27[[#This Row],[恒久工数]:[一時工数]]) -> 12 | J6: =_xlfn.XLOOKUP(T_FY27[[#This Row],[(作業用)タスク結合名]],FY26工数!$F:$F,FY26工数!$I:$I,0) -> 12 | K6: =_xlfn.LET( _xlpm.FY26恒久, _xlfn.XLOOKUP(T_FY27[[#This Row],[(作業用)タスク結合名]], T_FY26[(作業用)タスク結合名], T_FY26[恒久工数], 0), _xlpm.FY26一時, _xlfn.XLOOKUP(T_FY27[[#This Row],[(作業用)タスク結合名]], T_FY26[(作業用)タスク結合名], T_FY26[一時工数], 0), IF(T_FY27[[#This Row],[FY27工数]]<>T_FY27[[#This Row],[FY26工数]], IF(T_FY27[[#This Row],[FY26工数]]=0, "追加", IF(T_FY27[[#This Row],[FY27工数]]=0, "削除", "変更")), IF(OR(T_FY27[[#This Row],[恒久工数]]<>_xlpm.FY26恒久, T_FY27[[#This Row],[一時工数]]<>_xlpm.FY26一時), "内訳変更", "") ) ) | L6: =IF(T_FY27[[#This Row],[FY27工数]]=T_FY27[[#This Row],[FY26工数]], "", T_FY27[[#This Row],[FY27工数]]-T_FY27[[#This Row],[FY26工数]]) | M6: 2
A7: FFG | B7: ITGC | C7: RF | D7: B90A2 | E7: 勘定系・融資支援(MCインフラ束ね) | F7: =T_FY27[[#This Row],[Eng.]]&T_FY27[[#This Row],[大カテゴリ]]&T_FY27[[#This Row],[中カテゴリ]]&T_FY27[[#This Row],[タスク名]] -> FFGITGCRF勘定系・融資支援(MCインフラ束ね) | G7: 4 | I7: =SUM(T_FY27[[#This Row],[恒久工数]:[一時工数]]) -> 4 | J7: =_xlfn.XLOOKUP(T_FY27[[#This Row],[(作業用)タスク結合名]],FY26工数!$F:$F,FY26工数!$I:$I,0) -> 4 | K7: =_xlfn.LET( _xlpm.FY26恒久, _xlfn.XLOOKUP(T_FY27[[#This Row],[(作業用)タスク結合名]], T_FY26[(作業用)タスク結合名], T_FY26[恒久工数], 0), _xlpm.FY26一時, _xlfn.XLOOKUP(T_FY27[[#This Row],[(作業用)タスク結合名]], T_FY26[(作業用)タスク結合名], T_FY26[一時工数], 0), IF(T_FY27[[#This Row],[FY27工数]]<>T_FY27[[#This Row],[FY26工数]], IF(T_FY27[[#This Row],[FY26工数]]=0, "追加", IF(T_FY27[[#This Row],[FY27工数]]=0, "削除", "変更")), IF(OR(T_FY27[[#This Row],[恒久工数]]<>_xlpm.FY26恒久, T_FY27[[#This Row],[一時工数]]<>_xlpm.FY26一時), "内訳変更", "") ) ) | L7: =IF(T_FY27[[#This Row],[FY27工数]]=T_FY27[[#This Row],[FY26工数]], "", T_FY27[[#This Row],[FY27工数]]-T_FY27[[#This Row],[FY26工数]]) | M7: 4
A8: FFG | B8: ITGC | C8: WT | D8: B90A6 | E8: 勘定系・融資支援(MO障害束ね) | F8: =T_FY27[[#This Row],[Eng.]]&T_FY27[[#This Row],[大カテゴリ]]&T_FY27[[#This Row],[中カテゴリ]]&T_FY27[[#This Row],[タスク名]] -> FFGITGCWT勘定系・融資支援(MO障害束ね) | G8: 10 | I8: =SUM(T_FY27[[#This Row],[恒久工数]:[一時工数]]) -> 10 | J8: =_xlfn.XLOOKUP(T_FY27[[#This Row],[(作業用)タスク結合名]],FY26工数!$F:$F,FY26工数!$I:$I,0) -> 10 | K8: =_xlfn.LET( _xlpm.FY26恒久, _xlfn.XLOOKUP(T_FY27[[#This Row],[(作業用)タスク結合名]], T_FY26[(作業用)タスク結合名], T_FY26[恒久工数], 0), _xlpm.FY26一時, _xlfn.XLOOKUP(T_FY27[[#This Row],[(作業用)タスク結合名]], T_FY26[(作業用)タスク結合名], T_FY26[一時工数], 0), IF(T_FY27[[#This Row],[FY27工数]]<>T_FY27[[#This Row],[FY26工数]], IF(T_FY27[[#This Row],[FY26工数]]=0, "追加", IF(T_FY27[[#This Row],[FY27工数]]=0, "削除", "変更")), IF(OR(T_FY27[[#This Row],[恒久工数]]<>_xlpm.FY26恒久, T_FY27[[#This Row],[一時工数]]<>_xlpm.FY26一時), "内訳変更", "") ) ) | L8: =IF(T_FY27[[#This Row],[FY27工数]]=T_FY27[[#This Row],[FY26工数]], "", T_FY27[[#This Row],[FY27工数]]-T_FY27[[#This Row],[FY26工数]]) | M8: 9
A9: FFG | B9: ITGC | C9: TOC | D9: B90A6 | E9: 勘定系・融資支援(MO障害束ね) | F9: =T_FY27[[#This Row],[Eng.]]&T_FY27[[#This Row],[大カテゴリ]]&T_FY27[[#This Row],[中カテゴリ]]&T_FY27[[#This Row],[タスク名]] -> FFGITGCTOC勘定系・融資支援(MO障害束ね) | G9: 12 | I9: =SUM(T_FY27[[#This Row],[恒久工数]:[一時工数]]) -> 12 | J9: =_xlfn.XLOOKUP(T_FY27[[#This Row],[(作業用)タスク結合名]],FY26工数!$F:$F,FY26工数!$I:$I,0) -> 12 | K9: =_xlfn.LET( _xlpm.FY26恒久, _xlfn.XLOOKUP(T_FY27[[#This Row],[(作業用)タスク結合名]], T_FY26[(作業用)タスク結合名], T_FY26[恒久工数], 0), _xlpm.FY26一時, _xlfn.XLOOKUP(T_FY27[[#This Row],[(作業用)タスク結合名]], T_FY26[(作業用)タスク結合名], T_FY26[一時工数], 0), IF(T_FY27[[#This Row],[FY27工数]]<>T_FY27[[#This Row],[FY26工数]], IF(T_FY27[[#This Row],[FY26工数]]=0, "追加", IF(T_FY27[[#This Row],[FY27工数]]=0, "削除", "変更")), IF(OR(T_FY27[[#This Row],[恒久工数]]<>_xlpm.FY26恒久, T_FY27[[#This Row],[一時工数]]<>_xlpm.FY26一時), "内訳変更", "") ) ) | L9: =IF(T_FY27[[#This Row],[FY27工数]]=T_FY27[[#This Row],[FY26工数]], "", T_FY27[[#This Row],[FY27工数]]-T_FY27[[#This Row],[FY26工数]]) | M9: 2
A10: FFG | B10: ITGC | C10: RF | D10: B90A6 | E10: 勘定系・融資支援(MO障害束ね) | F10: =T_FY27[[#This Row],[Eng.]]&T_FY27[[#This Row],[大カテゴリ]]&T_FY27[[#This Row],[中カテゴリ]]&T_FY27[[#This Row],[タスク名]] -> FFGITGCRF勘定系・融資支援(MO障害束ね) | G10: 4 | I10: =SUM(T_FY27[[#This Row],[恒久工数]:[一時工数]]) -> 4 | J10: =_xlfn.XLOOKUP(T_FY27[[#This Row],[(作業用)タスク結合名]],FY26工数!$F:$F,FY26工数!$I:$I,0) -> 4 | K10: =_xlfn.LET( _xlpm.FY26恒久, _xlfn.XLOOKUP(T_FY27[[#This Row],[(作業用)タスク結合名]], T_FY26[(作業用)タスク結合名], T_FY26[恒久工数], 0), _xlpm.FY26一時, _xlfn.XLOOKUP(T_FY27[[#This Row],[(作業用)タスク結合名]], T_FY26[(作業用)タスク結合名], T_FY26[一時工数], 0), IF(T_FY27[[#This Row],[FY27工数]]<>T_FY27[[#This Row],[FY26工数]], IF(T_FY27[[#This Row],[FY26工数]]=0, "追加", IF(T_FY27[[#This Row],[FY27工数]]=0, "削除", "変更")), IF(OR(T_FY27[[#This Row],[恒久工数]]<>_xlpm.FY26恒久, T_FY27[[#This Row],[一時工数]]<>_xlpm.FY26一時), "内訳変更", "") ) ) | L10: =IF(T_FY27[[#This Row],[FY27工数]]=T_FY27[[#This Row],[FY26工数]], "", T_FY27[[#This Row],[FY27工数]]-T_FY27[[#This Row],[FY26工数]]) | M10: 4
A11: FFG | B11: ITGC | C11: WT | D11: B9021, B9023, B9024 | E11: 融資支援 | F11: =T_FY27[[#This Row],[Eng.]]&T_FY27[[#This Row],[大カテゴリ]]&T_FY27[[#This Row],[中カテゴリ]]&T_FY27[[#This Row],[タスク名]] -> FFGITGCWT融資支援 | G11: 33 | I11: =SUM(T_FY27[[#This Row],[恒久工数]:[一時工数]]) -> 33 | J11: =_xlfn.XLOOKUP(T_FY27[[#This Row],[(作業用)タスク結合名]],FY26工数!$F:$F,FY26工数!$I:$I,0) -> 33 | K11: =_xlfn.LET( _xlpm.FY26恒久, _xlfn.XLOOKUP(T_FY27[[#This Row],[(作業用)タスク結合名]], T_FY26[(作業用)タスク結合名], T_FY26[恒久工数], 0), _xlpm.FY26一時, _xlfn.XLOOKUP(T_FY27[[#This Row],[(作業用)タスク結合名]], T_FY26[(作業用)タスク結合名], T_FY26[一時工数], 0), IF(T_FY27[[#This Row],[FY27工数]]<>T_FY27[[#This Row],[FY26工数]], IF(T_FY27[[#This Row],[FY26工数]]=0, "追加", IF(T_FY27[[#This Row],[FY27工数]]=0, "削除", "変更")), IF(OR(T_FY27[[#This Row],[恒久工数]]<>_xlpm.FY26恒久, T_FY27[[#This Row],[一時工数]]<>_xlpm.FY26一時), "内訳変更", "") ) ) | L11: =IF(T_FY27[[#This Row],[FY27工数]]=T_FY27[[#This Row],[FY26工数]], "", T_FY27[[#This Row],[FY27工数]]-T_FY27[[#This Row],[FY26工数]]) | M11: 9
A12: FFG | B12: ITGC | C12: TOC | D12: B9021, B9023, B9024 | E12: 融資支援 | F12: =T_FY27[[#This Row],[Eng.]]&T_FY27[[#This Row],[大カテゴリ]]&T_FY27[[#This Row],[中カテゴリ]]&T_FY27[[#This Row],[タスク名]] -> FFGITGCTOC融資支援 | G12: 45 | I12: =SUM(T_FY27[[#This Row],[恒久工数]:[一時工数]]) -> 45 | J12: =_xlfn.XLOOKUP(T_FY27[[#This Row],[(作業用)タスク結合名]],FY26工数!$F:$F,FY26工数!$I:$I,0) -> 45 | K12: =_xlfn.LET( _xlpm.FY26恒久, _xlfn.XLOOKUP(T_FY27[[#This Row],[(作業用)タスク結合名]], T_FY26[(作業用)タスク結合名], T_FY26[恒久工数], 0), _xlpm.FY26一時, _xlfn.XLOOKUP(T_FY27[[#This Row],[(作業用)タスク結合名]], T_FY26[(作業用)タスク結合名], T_FY26[一時工数], 0), IF(T_FY27[[#This Row],[FY27工数]]<>T_FY27[[#This Row],[FY26工数]], IF(T_FY27[[#This Row],[FY26工数]]=0, "追加", IF(T_FY27[[#This Row],[FY27工数]]=0, "削除", "変更")), IF(OR(T_FY27[[#This Row],[恒久工数]]<>_xlpm.FY26恒久, T_FY27[[#This Row],[一時工数]]<>_xlpm.FY26一時), "内訳変更", "") ) ) | L12: =IF(T_FY27[[#This Row],[FY27工数]]=T_FY27[[#This Row],[FY26工数]], "", T_FY27[[#This Row],[FY27工数]]-T_FY27[[#This Row],[FY26工数]]) | M12: 2
A13: FFG | B13: ITGC | C13: RF | D13: B9021, B9023, B9024 | E13: 融資支援 | F13: =T_FY27[[#This Row],[Eng.]]&T_FY27[[#This Row],[大カテゴリ]]&T_FY27[[#This Row],[中カテゴリ]]&T_FY27[[#This Row],[タスク名]] -> FFGITGCRF融資支援 | G13: 6 | I13: =SUM(T_FY27[[#This Row],[恒久工数]:[一時工数]]) -> 6 | J13: =_xlfn.XLOOKUP(T_FY27[[#This Row],[(作業用)タスク結合名]],FY26工数!$F:$F,FY26工数!$I:$I,0) -> 6 | K13: =_xlfn.LET( _xlpm.FY26恒久, _xlfn.XLOOKUP(T_FY27[[#This Row],[(作業用)タスク結合名]], T_FY26[(作業用)タスク結合名], T_FY26[恒久工数], 0), _xlpm.FY26一時, _xlfn.XLOOKUP(T_FY27[[#This Row],[(作業用)タスク結合名]], T_FY26[(作業用)タスク結合名], T_FY26[一時工数], 0), IF(T_FY27[[#This Row],[FY27工数]]<>T_FY27[[#This Row],[FY26工数]], IF(T_FY27[[#This Row],[FY26工数]]=0, "追加", IF(T_FY27[[#This Row],[FY27工数]]=0, "削除", "変更")), IF(OR(T_FY27[[#This Row],[恒久工数]]<>_xlpm.FY26恒久, T_FY27[[#This Row],[一時工数]]<>_xlpm.FY26一時), "内訳変更", "") ) ) | L13: =IF(T_FY27[[#This Row],[FY27工数]]=T_FY27[[#This Row],[FY26工数]], "", T_FY27[[#This Row],[FY27工数]]-T_FY27[[#This Row],[FY26工数]]) | M13: 4
A14: FFG | B14: ITGC | C14: WT | D14: B9026 | E14: 融資支援(MO束ね) | F14: =T_FY27[[#This Row],[Eng.]]&T_FY27[[#This Row],[大カテゴリ]]&T_FY27[[#This Row],[中カテゴリ]]&T_FY27[[#This Row],[タスク名]] -> FFGITGCWT融資支援(MO束ね) | G14: 7 | I14: =SUM(T_FY27[[#This Row],[恒久工数]:[一時工数]]) -> 7 | J14: =_xlfn.XLOOKUP(T_FY27[[#This Row],[(作業用)タスク結合名]],FY26工数!$F:$F,FY26工数!$I:$I,0) -> 7 | K14: =_xlfn.LET( _xlpm.FY26恒久, _xlfn.XLOOKUP(T_FY27[[#This Row],[(作業用)タスク結合名]], T_FY26[(作業用)タスク結合名], T_FY26[恒久工数], 0), _xlpm.FY26一時, _xlfn.XLOOKUP(T_FY27[[#This Row],[(作業用)タスク結合名]], T_FY26[(作業用)タスク結合名], T_FY26[一時工数], 0), IF(T_FY27[[#This Row],[FY27工数]]<>T_FY27[[#This Row],[FY26工数]], IF(T_FY27[[#This Row],[FY26工数]]=0, "追加", IF(T_FY27[[#This Row],[FY27工数]]=0, "削除", "変更")), IF(OR(T_FY27[[#This Row],[恒久工数]]<>_xlpm.FY26恒久, T_FY27[[#This Row],[一時工数]]<>_xlpm.FY26一時), "内訳変更", "") ) ) | L14: =IF(T_FY27[[#This Row],[FY27工数]]=T_FY27[[#This Row],[FY26工数]], "", T_FY27[[#This Row],[FY27工数]]-T_FY27[[#This Row],[FY26工数]]) | M14: 9
A15: FFG | B15: ITGC | C15: TOC | D15: B9026 | E15: 融資支援(MO束ね) | F15: =T_FY27[[#This Row],[Eng.]]&T_FY27[[#This Row],[大カテゴリ]]&T_FY27[[#This Row],[中カテゴリ]]&T_FY27[[#This Row],[タスク名]] -> FFGITGCTOC融資支援(MO束ね) | G15: 8 | I15: =SUM(T_FY27[[#This Row],[恒久工数]:[一時工数]]) -> 8 | J15: =_xlfn.XLOOKUP(T_FY27[[#This Row],[(作業用)タスク結合名]],FY26工数!$F:$F,FY26工数!$I:$I,0) -> 8 | K15: =_xlfn.LET( _xlpm.FY26恒久, _xlfn.XLOOKUP(T_FY27[[#This Row],[(作業用)タスク結合名]], T_FY26[(作業用)タスク結合名], T_FY26[恒久工数], 0), _xlpm.FY26一時, _xlfn.XLOOKUP(T_FY27[[#This Row],[(作業用)タスク結合名]], T_FY26[(作業用)タスク結合名], T_FY26[一時工数], 0), IF(T_FY27[[#This Row],[FY27工数]]<>T_FY27[[#This Row],[FY26工数]], IF(T_FY27[[#This Row],[FY26工数]]=0, "追加", IF(T_FY27[[#This Row],[FY27工数]]=0, "削除", "変更")), IF(OR(T_FY27[[#This Row],[恒久工数]]<>_xlpm.FY26恒久, T_FY27[[#This Row],[一時工数]]<>_xlpm.FY26一時), "内訳変更", "") ) ) | L15: =IF(T_FY27[[#This Row],[FY27工数]]=T_FY27[[#This Row],[FY26工数]], "", T_FY27[[#This Row],[FY27工数]]-T_FY27[[#This Row],[FY26工数]]) | M15: 2
A16: FFG | B16: ITGC | C16: RF | D16: B9026 | E16: 融資支援(MO束ね) | F16: =T_FY27[[#This Row],[Eng.]]&T_FY27[[#This Row],[大カテゴリ]]&T_FY27[[#This Row],[中カテゴリ]]&T_FY27[[#This Row],[タスク名]] -> FFGITGCRF融資支援(MO束ね) | G16: 4 | I16: =SUM(T_FY27[[#This Row],[恒久工数]:[一時工数]]) -> 4 | J16: =_xlfn.XLOOKUP(T_FY27[[#This Row],[(作業用)タスク結合名]],FY26工数!$F:$F,FY26工数!$I:$I,0) -> 4 | K16: =_xlfn.LET( _xlpm.FY26恒久, _xlfn.XLOOKUP(T_FY27[[#This Row],[(作業用)タスク結合名]], T_FY26[(作業用)タスク結合名], T_FY26[恒久工数], 0), _xlpm.FY26一時, _xlfn.XLOOKUP(T_FY27[[#This Row],[(作業用)タスク結合名]], T_FY26[(作業用)タスク結合名], T_FY26[一時工数], 0), IF(T_FY27[[#This Row],[FY27工数]]<>T_FY27[[#This Row],[FY26工数]], IF(T_FY27[[#This Row],[FY26工数]]=0, "追加", IF(T_FY27[[#This Row],[FY27工数]]=0, "削除", "変更")), IF(OR(T_FY27[[#This Row],[恒久工数]]<>_xlpm.FY26恒久, T_FY27[[#This Row],[一時工数]]<>_xlpm.FY26一時), "内訳変更", "") ) ) | L16: =IF(T_FY27[[#This Row],[FY27工数]]=T_FY27[[#This Row],[FY26工数]], "", T_FY27[[#This Row],[FY27工数]]-T_FY27[[#This Row],[FY26工数]]) | M16: 4
A17: FFG | B17: ITGC | C17: WT | D17: B90H5 | E17: デ直束ね(融資支援・個人ローン・国際勘定) | F17: =T_FY27[[#This Row],[Eng.]]&T_FY27[[#This Row],[大カテゴリ]]&T_FY27[[#This Row],[中カテゴリ]]&T_FY27[[#This Row],[タスク名]] -> FFGITGCWTデ直束ね(融資支援・個人ローン・国際勘定) | G17: 17 | I17: =SUM(T_FY27[[#This Row],[恒久工数]:[一時工数]]) -> 17 | J17: =_xlfn.XLOOKUP(T_FY27[[#This Row],[(作業用)タスク結合名]],FY26工数!$F:$F,FY26工数!$I:$I,0) -> 17 | K17: =_xlfn.LET( _xlpm.FY26恒久, _xlfn.XLOOKUP(T_FY27[[#This Row],[(作業用)タスク結合名]], T_FY26[(作業用)タスク結合名], T_FY26[恒久工数], 0), _xlpm.FY26一時, _xlfn.XLOOKUP(T_FY27[[#This Row],[(作業用)タスク結合名]], T_FY26[(作業用)タスク結合名], T_FY26[一時工数], 0), IF(T_FY27[[#This Row],[FY27工数]]<>T_FY27[[#This Row],[FY26工数]], IF(T_FY27[[#This Row],[FY26工数]]=0, "追加", IF(T_FY27[[#This Row],[FY27工数]]=0, "削除", "変更")), IF(OR(T_FY27[[#This Row],[恒久工数]]<>_xlpm.FY26恒久, T_FY27[[#This Row],[一時工数]]<>_xlpm.FY26一時), "内訳変更", "") ) ) | L17: =IF(T_FY27[[#This Row],[FY27工数]]=T_FY27[[#This Row],[FY26工数]], "", T_FY27[[#This Row],[FY27工数]]-T_FY27[[#This Row],[FY26工数]]) | M17: 9
A18: FFG | B18: ITGC | C18: TOC | D18: B90H5 | E18: デ直束ね(融資支援・個人ローン・国際勘定) | F18: =T_FY27[[#This Row],[Eng.]]&T_FY27[[#This Row],[大カテゴリ]]&T_FY27[[#This Row],[中カテゴリ]]&T_FY27[[#This Row],[タスク名]] -> FFGITGCTOCデ直束ね(融資支援・個人ローン・国際勘定) | G18: 18 | I18: =SUM(T_FY27[[#This Row],[恒久工数]:[一時工数]]) -> 18 | J18: =_xlfn.XLOOKUP(T_FY27[[#This Row],[(作業用)タスク結合名]],FY26工数!$F:$F,FY26工数!$I:$I,0) -> 18 | K18: =_xlfn.LET( _xlpm.FY26恒久, _xlfn.XLOOKUP(T_FY27[[#This Row],[(作業用)タスク結合名]], T_FY26[(作業用)タスク結合名], T_FY26[恒久工数], 0), _xlpm.FY26一時, _xlfn.XLOOKUP(T_FY27[[#This Row],[(作業用)タスク結合名]], T_FY26[(作業用)タスク結合名], T_FY26[一時工数], 0), IF(T_FY27[[#This Row],[FY27工数]]<>T_FY27[[#This Row],[FY26工数]], IF(T_FY27[[#This Row],[FY26工数]]=0, "追加", IF(T_FY27[[#This Row],[FY27工数]]=0, "削除", "変更")), IF(OR(T_FY27[[#This Row],[恒久工数]]<>_xlpm.FY26恒久, T_FY27[[#This Row],[一時工数]]<>_xlpm.FY26一時), "内訳変更", "") ) ) | L18: =IF(T_FY27[[#This Row],[FY27工数]]=T_FY27[[#This Row],[FY26工数]], "", T_FY27[[#This Row],[FY27工数]]-T_FY27[[#This Row],[FY26工数]]) | M18: 2
A19: FFG | B19: ITGC | C19: RF | D19: B90H5 | E19: デ直束ね(融資支援・個人ローン・国際勘定) | F19: =T_FY27[[#This Row],[Eng.]]&T_FY27[[#This Row],[大カテゴリ]]&T_FY27[[#This Row],[中カテゴリ]]&T_FY27[[#This Row],[タスク名]] -> FFGITGCRFデ直束ね(融資支援・個人ローン・国際勘定) | G19: 4 | I19: =SUM(T_FY27[[#This Row],[恒久工数]:[一時工数]]) -> 4 | J19: =_xlfn.XLOOKUP(T_FY27[[#This Row],[(作業用)タスク結合名]],FY26工数!$F:$F,FY26工数!$I:$I,0) -> 4 | K19: =_xlfn.LET( _xlpm.FY26恒久, _xlfn.XLOOKUP(T_FY27[[#This Row],[(作業用)タスク結合名]], T_FY26[(作業用)タスク結合名], T_FY26[恒久工数], 0), _xlpm.FY26一時, _xlfn.XLOOKUP(T_FY27[[#This Row],[(作業用)タスク結合名]], T_FY26[(作業用)タスク結合名], T_FY26[一時工数], 0), IF(T_FY27[[#This Row],[FY27工数]]<>T_FY27[[#This Row],[FY26工数]], IF(T_FY27[[#This Row],[FY26工数]]=0, "追加", IF(T_FY27[[#This Row],[FY27工数]]=0, "削除", "変更")), IF(OR(T_FY27[[#This Row],[恒久工数]]<>_xlpm.FY26恒久, T_FY27[[#This Row],[一時工数]]<>_xlpm.FY26一時), "内訳変更", "") ) ) | L19: =IF(T_FY27[[#This Row],[FY27工数]]=T_FY27[[#This Row],[FY26工数]], "", T_FY27[[#This Row],[FY27工数]]-T_FY27[[#This Row],[FY26工数]]) | M19: 4
A20: FFG | B20: ITGC | C20: WT | E20: 本部決算(MAアプリ・MAインフラ) | F20: =T_FY27[[#This Row],[Eng.]]&T_FY27[[#This Row],[大カテゴリ]]&T_FY27[[#This Row],[中カテゴリ]]&T_FY27[[#This Row],[タスク名]] -> FFGITGCWT本部決算(MAアプリ・MAインフラ) | G20: 11 | I20: =SUM(T_FY27[[#This Row],[恒久工数]:[一時工数]]) -> 11 | J20: =_xlfn.XLOOKUP(T_FY27[[#This Row],[(作業用)タスク結合名]],FY26工数!$F:$F,FY26工数!$I:$I,0) -> 11 | K20: =_xlfn.LET( _xlpm.FY26恒久, _xlfn.XLOOKUP(T_FY27[[#This Row],[(作業用)タスク結合名]], T_FY26[(作業用)タスク結合名], T_FY26[恒久工数], 0), _xlpm.FY26一時, _xlfn.XLOOKUP(T_FY27[[#This Row],[(作業用)タスク結合名]], T_FY26[(作業用)タスク結合名], T_FY26[一時工数], 0), IF(T_FY27[[#This Row],[FY27工数]]<>T_FY27[[#This Row],[FY26工数]], IF(T_FY27[[#This Row],[FY26工数]]=0, "追加", IF(T_FY27[[#This Row],[FY27工数]]=0, "削除", "変更")), IF(OR(T_FY27[[#This Row],[恒久工数]]<>_xlpm.FY26恒久, T_FY27[[#This Row],[一時工数]]<>_xlpm.FY26一時), "内訳変更", "") ) ) | L20: =IF(T_FY27[[#This Row],[FY27工数]]=T_FY27[[#This Row],[FY26工数]], "", T_FY27[[#This Row],[FY27工数]]-T_FY27[[#This Row],[FY26工数]]) | M20: 9
A21: FFG | B21: ITGC | C21: TOC | E21: 本部決算(MAアプリ・MAインフラ) | F21: =T_FY27[[#This Row],[Eng.]]&T_FY27[[#This Row],[大カテゴリ]]&T_FY27[[#This Row],[中カテゴリ]]&T_FY27[[#This Row],[タスク名]] -> FFGITGCTOC本部決算(MAアプリ・MAインフラ) | G21: 11 | I21: =SUM(T_FY27[[#This Row],[恒久工数]:[一時工数]]) -> 11 | J21: =_xlfn.XLOOKUP(T_FY27[[#This Row],[(作業用)タスク結合名]],FY26工数!$F:$F,FY26工数!$I:$I,0) -> 11 | K21: =_xlfn.LET( _xlpm.FY26恒久, _xlfn.XLOOKUP(T_FY27[[#This Row],[(作業用)タスク結合名]], T_FY26[(作業用)タスク結合名], T_FY26[恒久工数], 0), _xlpm.FY26一時, _xlfn.XLOOKUP(T_FY27[[#This Row],[(作業用)タスク結合名]], T_FY26[(作業用)タスク結合名], T_FY26[一時工数], 0), IF(T_FY27[[#This Row],[FY27工数]]<>T_FY27[[#This Row],[FY26工数]], IF(T_FY27[[#This Row],[FY26工数]]=0, "追加", IF(T_FY27[[#This Row],[FY27工数]]=0, "削除", "変更")), IF(OR(T_FY27[[#This Row],[恒久工数]]<>_xlpm.FY26恒久, T_FY27[[#This Row],[一時工数]]<>_xlpm.FY26一時), "内訳変更", "") ) ) | L21: =IF(T_FY27[[#This Row],[FY27工数]]=T_FY27[[#This Row],[FY26工数]], "", T_FY27[[#This Row],[FY27工数]]-T_FY27[[#This Row],[FY26工数]]) | M21: 2
A22: FFG | B22: ITGC | C22: RF | E22: 本部決算(MAアプリ・MAインフラ) | F22: =T_FY27[[#This Row],[Eng.]]&T_FY27[[#This Row],[大カテゴリ]]&T_FY27[[#This Row],[中カテゴリ]]&T_FY27[[#This Row],[タスク名]] -> FFGITGCRF本部決算(MAアプリ・MAインフラ) | G22: 4 | I22: =SUM(T_FY27[[#This Row],[恒久工数]:[一時工数]]) -> 4 | J22: =_xlfn.XLOOKUP(T_FY27[[#This Row],[(作業用)タスク結合名]],FY26工数!$F:$F,FY26工数!$I:$I,0) -> 4 | K22: =_xlfn.LET( _xlpm.FY26恒久, _xlfn.XLOOKUP(T_FY27[[#This Row],[(作業用)タスク結合名]], T_FY26[(作業用)タスク結合名], T_FY26[恒久工数], 0), _xlpm.FY26一時, _xlfn.XLOOKUP(T_FY27[[#This Row],[(作業用)タスク結合名]], T_FY26[(作業用)タスク結合名], T_FY26[一時工数], 0), IF(T_FY27[[#This Row],[FY27工数]]<>T_FY27[[#This Row],[FY26工数]], IF(T_FY27[[#This Row],[FY26工数]]=0, "追加", IF(T_FY27[[#This Row],[FY27工数]]=0, "削除", "変更")), IF(OR(T_FY27[[#This Row],[恒久工数]]<>_xlpm.FY26恒久, T_FY27[[#This Row],[一時工数]]<>_xlpm.FY26一時), "内訳変更", "") ) ) | L22: =IF(T_FY27[[#This Row],[FY27工数]]=T_FY27[[#This Row],[FY26工数]], "", T_FY27[[#This Row],[FY27工数]]-T_FY27[[#This Row],[FY26工数]]) | M22: 4
A23: FFG | B23: ITGC | C23: WT | E23: (FFG) 勘定奉行＊ | F23: =T_FY27[[#This Row],[Eng.]]&T_FY27[[#This Row],[大カテゴリ]]&T_FY27[[#This Row],[中カテゴリ]]&T_FY27[[#This Row],[タスク名]] -> FFGITGCWT(FFG) 勘定奉行＊ | G23: 6 | I23: =SUM(T_FY27[[#This Row],[恒久工数]:[一時工数]]) -> 6 | J23: =_xlfn.XLOOKUP(T_FY27[[#This Row],[(作業用)タスク結合名]],FY26工数!$F:$F,FY26工数!$I:$I,0) -> 6 | K23: =_xlfn.LET( _xlpm.FY26恒久, _xlfn.XLOOKUP(T_FY27[[#This Row],[(作業用)タスク結合名]], T_FY26[(作業用)タスク結合名], T_FY26[恒久工数], 0), _xlpm.FY26一時, _xlfn.XLOOKUP(T_FY27[[#This Row],[(作業用)タスク結合名]], T_FY26[(作業用)タスク結合名], T_FY26[一時工数], 0), IF(T_FY27[[#This Row],[FY27工数]]<>T_FY27[[#This Row],[FY26工数]], IF(T_FY27[[#This Row],[FY26工数]]=0, "追加", IF(T_FY27[[#This Row],[FY27工数]]=0, "削除", "変更")), IF(OR(T_FY27[[#This Row],[恒久工数]]<>_xlpm.FY26恒久, T_FY27[[#This Row],[一時工数]]<>_xlpm.FY26一時), "内訳変更", "") ) ) | L23: =IF(T_FY27[[#This Row],[FY27工数]]=T_FY27[[#This Row],[FY26工数]], "", T_FY27[[#This Row],[FY27工数]]-T_FY27[[#This Row],[FY26工数]]) | M23: 9
A24: FFG | B24: ITGC | C24: TOC | E24: (FFG) 勘定奉行＊ | F24: =T_FY27[[#This Row],[Eng.]]&T_FY27[[#This Row],[大カテゴリ]]&T_FY27[[#This Row],[中カテゴリ]]&T_FY27[[#This Row],[タスク名]] -> FFGITGCTOC(FFG) 勘定奉行＊ | G24: 6 | I24: =SUM(T_FY27[[#This Row],[恒久工数]:[一時工数]]) -> 6 | J24: =_xlfn.XLOOKUP(T_FY27[[#This Row],[(作業用)タスク結合名]],FY26工数!$F:$F,FY26工数!$I:$I,0) -> 6 | K24: =_xlfn.LET( _xlpm.FY26恒久, _xlfn.XLOOKUP(T_FY27[[#This Row],[(作業用)タスク結合名]], T_FY26[(作業用)タスク結合名], T_FY26[恒久工数], 0), _xlpm.FY26一時, _xlfn.XLOOKUP(T_FY27[[#This Row],[(作業用)タスク結合名]], T_FY26[(作業用)タスク結合名], T_FY26[一時工数], 0), IF(T_FY27[[#This Row],[FY27工数]]<>T_FY27[[#This Row],[FY26工数]], IF(T_FY27[[#This Row],[FY26工数]]=0, "追加", IF(T_FY27[[#This Row],[FY27工数]]=0, "削除", "変更")), IF(OR(T_FY27[[#This Row],[恒久工数]]<>_xlpm.FY26恒久, T_FY27[[#This Row],[一時工数]]<>_xlpm.FY26一時), "内訳変更", "") ) ) | L24: =IF(T_FY27[[#This Row],[FY27工数]]=T_FY27[[#This Row],[FY26工数]], "", T_FY27[[#This Row],[FY27工数]]-T_FY27[[#This Row],[FY26工数]]) | M24: 2
A25: FFG | B25: ITGC | C25: RF | E25: (FFG) 勘定奉行＊ | F25: =T_FY27[[#This Row],[Eng.]]&T_FY27[[#This Row],[大カテゴリ]]&T_FY27[[#This Row],[中カテゴリ]]&T_FY27[[#This Row],[タスク名]] -> FFGITGCRF(FFG) 勘定奉行＊ | G25: 4 | I25: =SUM(T_FY27[[#This Row],[恒久工数]:[一時工数]]) -> 4 | J25: =_xlfn.XLOOKUP(T_FY27[[#This Row],[(作業用)タスク結合名]],FY26工数!$F:$F,FY26工数!$I:$I,0) -> 4 | K25: =_xlfn.LET( _xlpm.FY26恒久, _xlfn.XLOOKUP(T_FY27[[#This Row],[(作業用)タスク結合名]], T_FY26[(作業用)タスク結合名], T_FY26[恒久工数], 0), _xlpm.FY26一時, _xlfn.XLOOKUP(T_FY27[[#This Row],[(作業用)タスク結合名]], T_FY26[(作業用)タスク結合名], T_FY26[一時工数], 0), IF(T_FY27[[#This Row],[FY27工数]]<>T_FY27[[#This Row],[FY26工数]], IF(T_FY27[[#This Row],[FY26工数]]=0, "追加", IF(T_FY27[[#This Row],[FY27工数]]=0, "削除", "変更")), IF(OR(T_FY27[[#This Row],[恒久工数]]<>_xlpm.FY26恒久, T_FY27[[#This Row],[一時工数]]<>_xlpm.FY26一時), "内訳変更", "") ) ) | L25: =IF(T_FY27[[#This Row],[FY27工数]]=T_FY27[[#This Row],[FY26工数]], "", T_FY27[[#This Row],[FY27工数]]-T_FY27[[#This Row],[FY26工数]]) | M25: 4
A26: FFG | B26: ITGC | C26: WT | E26: (FFG) 連結納税＊ | F26: =T_FY27[[#This Row],[Eng.]]&T_FY27[[#This Row],[大カテゴリ]]&T_FY27[[#This Row],[中カテゴリ]]&T_FY27[[#This Row],[タスク名]] -> FFGITGCWT(FFG) 連結納税＊ | G26: 6 | I26: =SUM(T_FY27[[#This Row],[恒久工数]:[一時工数]]) -> 6 | J26: =_xlfn.XLOOKUP(T_FY27[[#This Row],[(作業用)タスク結合名]],FY26工数!$F:$F,FY26工数!$I:$I,0) -> 6 | K26: =_xlfn.LET( _xlpm.FY26恒久, _xlfn.XLOOKUP(T_FY27[[#This Row],[(作業用)タスク結合名]], T_FY26[(作業用)タスク結合名], T_FY26[恒久工数], 0), _xlpm.FY26一時, _xlfn.XLOOKUP(T_FY27[[#This Row],[(作業用)タスク結合名]], T_FY26[(作業用)タスク結合名], T_FY26[一時工数], 0), IF(T_FY27[[#This Row],[FY27工数]]<>T_FY27[[#This Row],[FY26工数]], IF(T_FY27[[#This Row],[FY26工数]]=0, "追加", IF(T_FY27[[#This Row],[FY27工数]]=0, "削除", "変更")), IF(OR(T_FY27[[#This Row],[恒久工数]]<>_xlpm.FY26恒久, T_FY27[[#This Row],[一時工数]]<>_xlpm.FY26一時), "内訳変更", "") ) ) | L26: =IF(T_FY27[[#This Row],[FY27工数]]=T_FY27[[#This Row],[FY26工数]], "", T_FY27[[#This Row],[FY27工数]]-T_FY27[[#This Row],[FY26工数]]) | M26: 9
A27: FFG | B27: ITGC | C27: TOC | E27: (FFG) 連結納税＊ | F27: =T_FY27[[#This Row],[Eng.]]&T_FY27[[#This Row],[大カテゴリ]]&T_FY27[[#This Row],[中カテゴリ]]&T_FY27[[#This Row],[タスク名]] -> FFGITGCTOC(FFG) 連結納税＊ | G27: 6 | I27: =SUM(T_FY27[[#This Row],[恒久工数]:[一時工数]]) -> 6 | J27: =_xlfn.XLOOKUP(T_FY27[[#This Row],[(作業用)タスク結合名]],FY26工数!$F:$F,FY26工数!$I:$I,0) -> 6 | K27: =_xlfn.LET( _xlpm.FY26恒久, _xlfn.XLOOKUP(T_FY27[[#This Row],[(作業用)タスク結合名]], T_FY26[(作業用)タスク結合名], T_FY26[恒久工数], 0), _xlpm.FY26一時, _xlfn.XLOOKUP(T_FY27[[#This Row],[(作業用)タスク結合名]], T_FY26[(作業用)タスク結合名], T_FY26[一時工数], 0), IF(T_FY27[[#This Row],[FY27工数]]<>T_FY27[[#This Row],[FY26工数]], IF(T_FY27[[#This Row],[FY26工数]]=0, "追加", IF(T_FY27[[#This Row],[FY27工数]]=0, "削除", "変更")), IF(OR(T_FY27[[#This Row],[恒久工数]]<>_xlpm.FY26恒久, T_FY27[[#This Row],[一時工数]]<>_xlpm.FY26一時), "内訳変更", "") ) ) | L27: =IF(T_FY27[[#This Row],[FY27工数]]=T_FY27[[#This Row],[FY26工数]], "", T_FY27[[#This Row],[FY27工数]]-T_FY27[[#This Row],[FY26工数]]) | M27: 2
A28: FFG | B28: ITGC | C28: RF | E28: (FFG) 連結納税＊ | F28: =T_FY27[[#This Row],[Eng.]]&T_FY27[[#This Row],[大カテゴリ]]&T_FY27[[#This Row],[中カテゴリ]]&T_FY27[[#This Row],[タスク名]] -> FFGITGCRF(FFG) 連結納税＊ | G28: 5 | I28: =SUM(T_FY27[[#This Row],[恒久工数]:[一時工数]]) -> 5 | J28: =_xlfn.XLOOKUP(T_FY27[[#This Row],[(作業用)タスク結合名]],FY26工数!$F:$F,FY26工数!$I:$I,0) -> 5 | K28: =_xlfn.LET( _xlpm.FY26恒久, _xlfn.XLOOKUP(T_FY27[[#This Row],[(作業用)タスク結合名]], T_FY26[(作業用)タスク結合名], T_FY26[恒久工数], 0), _xlpm.FY26一時, _xlfn.XLOOKUP(T_FY27[[#This Row],[(作業用)タスク結合名]], T_FY26[(作業用)タスク結合名], T_FY26[一時工数], 0), IF(T_FY27[[#This Row],[FY27工数]]<>T_FY27[[#This Row],[FY26工数]], IF(T_FY27[[#This Row],[FY26工数]]=0, "追加", IF(T_FY27[[#This Row],[FY27工数]]=0, "削除", "変更")), IF(OR(T_FY27[[#This Row],[恒久工数]]<>_xlpm.FY26恒久, T_FY27[[#This Row],[一時工数]]<>_xlpm.FY26一時), "内訳変更", "") ) ) | L28: =IF(T_FY27[[#This Row],[FY27工数]]=T_FY27[[#This Row],[FY26工数]], "", T_FY27[[#This Row],[FY27工数]]-T_FY27[[#This Row],[FY26工数]]) | M28: 4
A29: FFG | B29: ITGC | C29: WT | D29: B90B1 | E29: MC束ね(本部決裁・個人ローン・投資経費) | F29: =T_FY27[[#This Row],[Eng.]]&T_FY27[[#This Row],[大カテゴリ]]&T_FY27[[#This Row],[中カテゴリ]]&T_FY27[[#This Row],[タスク名]] -> FFGITGCWTMC束ね(本部決裁・個人ローン・投資経費) | G29: 19 | I29: =SUM(T_FY27[[#This Row],[恒久工数]:[一時工数]]) -> 19 | J29: =_xlfn.XLOOKUP(T_FY27[[#This Row],[(作業用)タスク結合名]],FY26工数!$F:$F,FY26工数!$I:$I,0) -> 19 | K29: =_xlfn.LET( _xlpm.FY26恒久, _xlfn.XLOOKUP(T_FY27[[#This Row],[(作業用)タスク結合名]], T_FY26[(作業用)タスク結合名], T_FY26[恒久工数], 0), _xlpm.FY26一時, _xlfn.XLOOKUP(T_FY27[[#This Row],[(作業用)タスク結合名]], T_FY26[(作業用)タスク結合名], T_FY26[一時工数], 0), IF(T_FY27[[#This Row],[FY27工数]]<>T_FY27[[#This Row],[FY26工数]], IF(T_FY27[[#This Row],[FY26工数]]=0, "追加", IF(T_FY27[[#This Row],[FY27工数]]=0, "削除", "変更")), IF(OR(T_FY27[[#This Row],[恒久工数]]<>_xlpm.FY26恒久, T_FY27[[#This Row],[一時工数]]<>_xlpm.FY26一時), "内訳変更", "") ) ) | L29: =IF(T_FY27[[#This Row],[FY27工数]]=T_FY27[[#This Row],[FY26工数]], "", T_FY27[[#This Row],[FY27工数]]-T_FY27[[#This Row],[FY26工数]]) | M29: 9
A30: FFG | B30: ITGC | C30: TOC | D30: B90B1 | E30: MC束ね(本部決裁・個人ローン・投資経費) | F30: =T_FY27[[#This Row],[Eng.]]&T_FY27[[#This Row],[大カテゴリ]]&T_FY27[[#This Row],[中カテゴリ]]&T_FY27[[#This Row],[タスク名]] -> FFGITGCTOCMC束ね(本部決裁・個人ローン・投資経費) | G30: 21 | I30: =SUM(T_FY27[[#This Row],[恒久工数]:[一時工数]]) -> 21 | J30: =_xlfn.XLOOKUP(T_FY27[[#This Row],[(作業用)タスク結合名]],FY26工数!$F:$F,FY26工数!$I:$I,0) -> 21 | K30: =_xlfn.LET( _xlpm.FY26恒久, _xlfn.XLOOKUP(T_FY27[[#This Row],[(作業用)タスク結合名]], T_FY26[(作業用)タスク結合名], T_FY26[恒久工数], 0), _xlpm.FY26一時, _xlfn.XLOOKUP(T_FY27[[#This Row],[(作業用)タスク結合名]], T_FY26[(作業用)タスク結合名], T_FY26[一時工数], 0), IF(T_FY27[[#This Row],[FY27工数]]<>T_FY27[[#This Row],[FY26工数]], IF(T_FY27[[#This Row],[FY26工数]]=0, "追加", IF(T_FY27[[#This Row],[FY27工数]]=0, "削除", "変更")), IF(OR(T_FY27[[#This Row],[恒久工数]]<>_xlpm.FY26恒久, T_FY27[[#This Row],[一時工数]]<>_xlpm.FY26一時), "内訳変更", "") ) ) | L30: =IF(T_FY27[[#This Row],[FY27工数]]=T_FY27[[#This Row],[FY26工数]], "", T_FY27[[#This Row],[FY27工数]]-T_FY27[[#This Row],[FY26工数]]) | M30: 2
A31: FFG | B31: ITGC | C31: RF | D31: B90B1 | E31: MC束ね(本部決裁・個人ローン・投資経費) | F31: =T_FY27[[#This Row],[Eng.]]&T_FY27[[#This Row],[大カテゴリ]]&T_FY27[[#This Row],[中カテゴリ]]&T_FY27[[#This Row],[タスク名]] -> FFGITGCRFMC束ね(本部決裁・個人ローン・投資経費) | G31: 6 | I31: =SUM(T_FY27[[#This Row],[恒久工数]:[一時工数]]) -> 6 | J31: =_xlfn.XLOOKUP(T_FY27[[#This Row],[(作業用)タスク結合名]],FY26工数!$F:$F,FY26工数!$I:$I,0) -> 6 | K31: =_xlfn.LET( _xlpm.FY26恒久, _xlfn.XLOOKUP(T_FY27[[#This Row],[(作業用)タスク結合名]], T_FY26[(作業用)タスク結合名], T_FY26[恒久工数], 0), _xlpm.FY26一時, _xlfn.XLOOKUP(T_FY27[[#This Row],[(作業用)タスク結合名]], T_FY26[(作業用)タスク結合名], T_FY26[一時工数], 0), IF(T_FY27[[#This Row],[FY27工数]]<>T_FY27[[#This Row],[FY26工数]], IF(T_FY27[[#This Row],[FY26工数]]=0, "追加", IF(T_FY27[[#This Row],[FY27工数]]=0, "削除", "変更")), IF(OR(T_FY27[[#This Row],[恒久工数]]<>_xlpm.FY26恒久, T_FY27[[#This Row],[一時工数]]<>_xlpm.FY26一時), "内訳変更", "") ) ) | L31: =IF(T_FY27[[#This Row],[FY27工数]]=T_FY27[[#This Row],[FY26工数]], "", T_FY27[[#This Row],[FY27工数]]-T_FY27[[#This Row],[FY26工数]]) | M31: 4
A32: FFG | B32: ITGC | C32: WT | D32: B90C1 | E32: MC束ね(不動産・人事・Siatol・国際・収益・財務・時価・固定資産) | F32: =T_FY27[[#This Row],[Eng.]]&T_FY27[[#This Row],[大カテゴリ]]&T_FY27[[#This Row],[中カテゴリ]]&T_FY27[[#This Row],[タスク名]] -> FFGITGCWTMC束ね(不動産・人事・Siatol・国際・収益・財務・時価・固定資産) | G32: 18 | H32: 1 | I32: =SUM(T_FY27[[#This Row],[恒久工数]:[一時工数]]) -> 19 | J32: =_xlfn.XLOOKUP(T_FY27[[#This Row],[(作業用)タスク結合名]],FY26工数!$F:$F,FY26工数!$I:$I,0) -> 19 | K32: =_xlfn.LET( _xlpm.FY26恒久, _xlfn.XLOOKUP(T_FY27[[#This Row],[(作業用)タスク結合名]], T_FY26[(作業用)タスク結合名], T_FY26[恒久工数], 0), _xlpm.FY26一時, _xlfn.XLOOKUP(T_FY27[[#This Row],[(作業用)タスク結合名]], T_FY26[(作業用)タスク結合名], T_FY26[一時工数], 0), IF(T_FY27[[#This Row],[FY27工数]]<>T_FY27[[#This Row],[FY26工数]], IF(T_FY27[[#This Row],[FY26工数]]=0, "追加", IF(T_FY27[[#This Row],[FY27工数]]=0, "削除", "変更")), IF(OR(T_FY27[[#This Row],[恒久工数]]<>_xlpm.FY26恒久, T_FY27[[#This Row],[一時工数]]<>_xlpm.FY26一時), "内訳変更", "") ) ) -> 内訳変更 | L32: =IF(T_FY27[[#This Row],[FY27工数]]=T_FY27[[#This Row],[FY26工数]], "", T_FY27[[#This Row],[FY27工数]]-T_FY27[[#This Row],[FY26工数]]) | M32: 9 | Q32: 人事情報束ね分離
A33: FFG | B33: ITGC | C33: TOC | D33: B90C1 | E33: MC束ね(不動産・人事・Siatol・国際・収益・財務・時価・固定資産) | F33: =T_FY27[[#This Row],[Eng.]]&T_FY27[[#This Row],[大カテゴリ]]&T_FY27[[#This Row],[中カテゴリ]]&T_FY27[[#This Row],[タスク名]] -> FFGITGCTOCMC束ね(不動産・人事・Siatol・国際・収益・財務・時価・固定資産) | G33: 20 | H33: 1 | I33: =SUM(T_FY27[[#This Row],[恒久工数]:[一時工数]]) -> 21 | J33: =_xlfn.XLOOKUP(T_FY27[[#This Row],[(作業用)タスク結合名]],FY26工数!$F:$F,FY26工数!$I:$I,0) -> 21 | K33: =_xlfn.LET( _xlpm.FY26恒久, _xlfn.XLOOKUP(T_FY27[[#This Row],[(作業用)タスク結合名]], T_FY26[(作業用)タスク結合名], T_FY26[恒久工数], 0), _xlpm.FY26一時, _xlfn.XLOOKUP(T_FY27[[#This Row],[(作業用)タスク結合名]], T_FY26[(作業用)タスク結合名], T_FY26[一時工数], 0), IF(T_FY27[[#This Row],[FY27工数]]<>T_FY27[[#This Row],[FY26工数]], IF(T_FY27[[#This Row],[FY26工数]]=0, "追加", IF(T_FY27[[#This Row],[FY27工数]]=0, "削除", "変更")), IF(OR(T_FY27[[#This Row],[恒久工数]]<>_xlpm.FY26恒久, T_FY27[[#This Row],[一時工数]]<>_xlpm.FY26一時), "内訳変更", "") ) ) -> 内訳変更 | L33: =IF(T_FY27[[#This Row],[FY27工数]]=T_FY27[[#This Row],[FY26工数]], "", T_FY27[[#This Row],[FY27工数]]-T_FY27[[#This Row],[FY26工数]]) | M33: 2 | Q33: 人事情報束ね分離
A34: FFG | B34: ITGC | C34: RF | D34: B90C1 | E34: MC束ね(不動産・人事・Siatol・国際・収益・財務・時価・固定資産) | F34: =T_FY27[[#This Row],[Eng.]]&T_FY27[[#This Row],[大カテゴリ]]&T_FY27[[#This Row],[中カテゴリ]]&T_FY27[[#This Row],[タスク名]] -> FFGITGCRFMC束ね(不動産・人事・Siatol・国際・収益・財務・時価・固定資産) | G34: 7 | I34: =SUM(T_FY27[[#This Row],[恒久工数]:[一時工数]]) -> 7 | J34: =_xlfn.XLOOKUP(T_FY27[[#This Row],[(作業用)タスク結合名]],FY26工数!$F:$F,FY26工数!$I:$I,0) -> 7 | K34: =_xlfn.LET( _xlpm.FY26恒久, _xlfn.XLOOKUP(T_FY27[[#This Row],[(作業用)タスク結合名]], T_FY26[(作業用)タスク結合名], T_FY26[恒久工数], 0), _xlpm.FY26一時, _xlfn.XLOOKUP(T_FY27[[#This Row],[(作業用)タスク結合名]], T_FY26[(作業用)タスク結合名], T_FY26[一時工数], 0), IF(T_FY27[[#This Row],[FY27工数]]<>T_FY27[[#This Row],[FY26工数]], IF(T_FY27[[#This Row],[FY26工数]]=0, "追加", IF(T_FY27[[#This Row],[FY27工数]]=0, "削除", "変更")), IF(OR(T_FY27[[#This Row],[恒久工数]]<>_xlpm.FY26恒久, T_FY27[[#This Row],[一時工数]]<>_xlpm.FY26一時), "内訳変更", "") ) ) | L34: =IF(T_FY27[[#This Row],[FY27工数]]=T_FY27[[#This Row],[FY26工数]], "", T_FY27[[#This Row],[FY27工数]]-T_FY27[[#This Row],[FY26工数]]) | M34: 4
A35: FFG | B35: ITGC | C35: WT | E35: Siatol MC | F35: =T_FY27[[#This Row],[Eng.]]&T_FY27[[#This Row],[大カテゴリ]]&T_FY27[[#This Row],[中カテゴリ]]&T_FY27[[#This Row],[タスク名]] -> FFGITGCWTSiatol MC | G35: 7 | H35: 3 | I35: =SUM(T_FY27[[#This Row],[恒久工数]:[一時工数]]) -> 10 | J35: =_xlfn.XLOOKUP(T_FY27[[#This Row],[(作業用)タスク結合名]],FY26工数!$F:$F,FY26工数!$I:$I,0) -> 0 | K35: =_xlfn.LET( _xlpm.FY26恒久, _xlfn.XLOOKUP(T_FY27[[#This Row],[(作業用)タスク結合名]], T_FY26[(作業用)タスク結合名], T_FY26[恒久工数], 0), _xlpm.FY26一時, _xlfn.XLOOKUP(T_FY27[[#This Row],[(作業用)タスク結合名]], T_FY26[(作業用)タスク結合名], T_FY26[一時工数], 0), IF(T_FY27[[#This Row],[FY27工数]]<>T_FY27[[#This Row],[FY26工数]], IF(T_FY27[[#This Row],[FY26工数]]=0, "追加", IF(T_FY27[[#This Row],[FY27工数]]=0, "削除", "変更")), IF(OR(T_FY27[[#This Row],[恒久工数]]<>_xlpm.FY26恒久, T_FY27[[#This Row],[一時工数]]<>_xlpm.FY26一時), "内訳変更", "") ) ) -> 追加 | L35: =IF(T_FY27[[#This Row],[FY27工数]]=T_FY27[[#This Row],[FY26工数]], "", T_FY27[[#This Row],[FY27工数]]-T_FY27[[#This Row],[FY26工数]]) -> 10 | M35: 9 | Q35: FY27 Siatolのクラウド更改
A36: FFG | B36: ITGC | C36: WT | E36: Siatol MO | F36: =T_FY27[[#This Row],[Eng.]]&T_FY27[[#This Row],[大カテゴリ]]&T_FY27[[#This Row],[中カテゴリ]]&T_FY27[[#This Row],[タスク名]] -> FFGITGCWTSiatol MO | G36: 6 | H36: 2 | I36: =SUM(T_FY27[[#This Row],[恒久工数]:[一時工数]]) -> 8 | J36: =_xlfn.XLOOKUP(T_FY27[[#This Row],[(作業用)タスク結合名]],FY26工数!$F:$F,FY26工数!$I:$I,0) -> 0 | K36: =_xlfn.LET( _xlpm.FY26恒久, _xlfn.XLOOKUP(T_FY27[[#This Row],[(作業用)タスク結合名]], T_FY26[(作業用)タスク結合名], T_FY26[恒久工数], 0), _xlpm.FY26一時, _xlfn.XLOOKUP(T_FY27[[#This Row],[(作業用)タスク結合名]], T_FY26[(作業用)タスク結合名], T_FY26[一時工数], 0), IF(T_FY27[[#This Row],[FY27工数]]<>T_FY27[[#This Row],[FY26工数]], IF(T_FY27[[#This Row],[FY26工数]]=0, "追加", IF(T_FY27[[#This Row],[FY27工数]]=0, "削除", "変更")), IF(OR(T_FY27[[#This Row],[恒久工数]]<>_xlpm.FY26恒久, T_FY27[[#This Row],[一時工数]]<>_xlpm.FY26一時), "内訳変更", "") ) ) -> 追加 | L36: =IF(T_FY27[[#This Row],[FY27工数]]=T_FY27[[#This Row],[FY26工数]], "", T_FY27[[#This Row],[FY27工数]]-T_FY27[[#This Row],[FY26工数]]) -> 8 | M36: 9 | Q36: FY27 Siatolのクラウド更改
A37: FFG | B37: ITGC | C37: WT | E37: MA(不動産・人事・Siatol・財務・時価) | F37: =T_FY27[[#This Row],[Eng.]]&T_FY27[[#This Row],[大カテゴリ]]&T_FY27[[#This Row],[中カテゴリ]]&T_FY27[[#This Row],[タスク名]] -> FFGITGCWTMA(不動産・人事・Siatol・財務・時価) | G37: 18 | H37: 2 | I37: =SUM(T_FY27[[#This Row],[恒久工数]:[一時工数]]) -> 20 | J37: =_xlfn.XLOOKUP(T_FY27[[#This Row],[(作業用)タスク結合名]],FY26工数!$F:$F,FY26工数!$I:$I,0) -> 19 | K37: =_xlfn.LET( _xlpm.FY26恒久, _xlfn.XLOOKUP(T_FY27[[#This Row],[(作業用)タスク結合名]], T_FY26[(作業用)タスク結合名], T_FY26[恒久工数], 0), _xlpm.FY26一時, _xlfn.XLOOKUP(T_FY27[[#This Row],[(作業用)タスク結合名]], T_FY26[(作業用)タスク結合名], T_FY26[一時工数], 0), IF(T_FY27[[#This Row],[FY27工数]]<>T_FY27[[#This Row],[FY26工数]], IF(T_FY27[[#This Row],[FY26工数]]=0, "追加", IF(T_FY27[[#This Row],[FY27工数]]=0, "削除", "変更")), IF(OR(T_FY27[[#This Row],[恒久工数]]<>_xlpm.FY26恒久, T_FY27[[#This Row],[一時工数]]<>_xlpm.FY26一時), "内訳変更", "") ) ) -> 変更 | L37: =IF(T_FY27[[#This Row],[FY27工数]]=T_FY27[[#This Row],[FY26工数]], "", T_FY27[[#This Row],[FY27工数]]-T_FY27[[#This Row],[FY26工数]]) -> 1 | M37: 9 | Q37: 人事情報束ね分離
A38: FFG | B38: ITGC | C38: TOC | E38: MA(不動産・人事・Siatol・財務・時価) | F38: =T_FY27[[#This Row],[Eng.]]&T_FY27[[#This Row],[大カテゴリ]]&T_FY27[[#This Row],[中カテゴリ]]&T_FY27[[#This Row],[タスク名]] -> FFGITGCTOCMA(不動産・人事・Siatol・財務・時価) | G38: 20 | H38: 3 | I38: =SUM(T_FY27[[#This Row],[恒久工数]:[一時工数]]) -> 23 | J38: =_xlfn.XLOOKUP(T_FY27[[#This Row],[(作業用)タスク結合名]],FY26工数!$F:$F,FY26工数!$I:$I,0) -> 21 | K38: =_xlfn.LET( _xlpm.FY26恒久, _xlfn.XLOOKUP(T_FY27[[#This Row],[(作業用)タスク結合名]], T_FY26[(作業用)タスク結合名], T_FY26[恒久工数], 0), _xlpm.FY26一時, _xlfn.XLOOKUP(T_FY27[[#This Row],[(作業用)タスク結合名]], T_FY26[(作業用)タスク結合名], T_FY26[一時工数], 0), IF(T_FY27[[#This Row],[FY27工数]]<>T_FY27[[#This Row],[FY26工数]], IF(T_FY27[[#This Row],[FY26工数]]=0, "追加", IF(T_FY27[[#This Row],[FY27工数]]=0, "削除", "変更")), IF(OR(T_FY27[[#This Row],[恒久工数]]<>_xlpm.FY26恒久, T_FY27[[#This Row],[一時工数]]<>_xlpm.FY26一時), "内訳変更", "") ) ) -> 変更 | L38: =IF(T_FY27[[#This Row],[FY27工数]]=T_FY27[[#This Row],[FY26工数]], "", T_FY27[[#This Row],[FY27工数]]-T_FY27[[#This Row],[FY26工数]]) -> 2 | M38: 2 | Q38: 人事情報束ね分離
A39: FFG | B39: ITGC | C39: RF | E39: MA(不動産・人事・Siatol・財務・時価) | F39: =T_FY27[[#This Row],[Eng.]]&T_FY27[[#This Row],[大カテゴリ]]&T_FY27[[#This Row],[中カテゴリ]]&T_FY27[[#This Row],[タスク名]] -> FFGITGCRFMA(不動産・人事・Siatol・財務・時価) | G39: 7 | I39: =SUM(T_FY27[[#This Row],[恒久工数]:[一時工数]]) -> 7 | J39: =_xlfn.XLOOKUP(T_FY27[[#This Row],[(作業用)タスク結合名]],FY26工数!$F:$F,FY26工数!$I:$I,0) -> 7 | K39: =_xlfn.LET( _xlpm.FY26恒久, _xlfn.XLOOKUP(T_FY27[[#This Row],[(作業用)タスク結合名]], T_FY26[(作業用)タスク結合名], T_FY26[恒久工数], 0), _xlpm.FY26一時, _xlfn.XLOOKUP(T_FY27[[#This Row],[(作業用)タスク結合名]], T_FY26[(作業用)タスク結合名], T_FY26[一時工数], 0), IF(T_FY27[[#This Row],[FY27工数]]<>T_FY27[[#This Row],[FY26工数]], IF(T_FY27[[#This Row],[FY26工数]]=0, "追加", IF(T_FY27[[#This Row],[FY27工数]]=0, "削除", "変更")), IF(OR(T_FY27[[#This Row],[恒久工数]]<>_xlpm.FY26恒久, T_FY27[[#This Row],[一時工数]]<>_xlpm.FY26一時), "内訳変更", "") ) ) | L39: =IF(T_FY27[[#This Row],[FY27工数]]=T_FY27[[#This Row],[FY26工数]], "", T_FY27[[#This Row],[FY27工数]]-T_FY27[[#This Row],[FY26工数]]) | M39: 4
A40: FFG | B40: ITGC | C40: WT | D40: B9093 | E40: 国際勘定(MA) | F40: =T_FY27[[#This Row],[Eng.]]&T_FY27[[#This Row],[大カテゴリ]]&T_FY27[[#This Row],[中カテゴリ]]&T_FY27[[#This Row],[タスク名]] -> FFGITGCWT国際勘定(MA) | G40: 7 | I40: =SUM(T_FY27[[#This Row],[恒久工数]:[一時工数]]) -> 7 | J40: =_xlfn.XLOOKUP(T_FY27[[#This Row],[(作業用)タスク結合名]],FY26工数!$F:$F,FY26工数!$I:$I,0) -> 7 | K40: =_xlfn.LET( _xlpm.FY26恒久, _xlfn.XLOOKUP(T_FY27[[#This Row],[(作業用)タスク結合名]], T_FY26[(作業用)タスク結合名], T_FY26[恒久工数], 0), _xlpm.FY26一時, _xlfn.XLOOKUP(T_FY27[[#This Row],[(作業用)タスク結合名]], T_FY26[(作業用)タスク結合名], T_FY26[一時工数], 0), IF(T_FY27[[#This Row],[FY27工数]]<>T_FY27[[#This Row],[FY26工数]], IF(T_FY27[[#This Row],[FY26工数]]=0, "追加", IF(T_FY27[[#This Row],[FY27工数]]=0, "削除", "変更")), IF(OR(T_FY27[[#This Row],[恒久工数]]<>_xlpm.FY26恒久, T_FY27[[#This Row],[一時工数]]<>_xlpm.FY26一時), "内訳変更", "") ) ) | L40: =IF(T_FY27[[#This Row],[FY27工数]]=T_FY27[[#This Row],[FY26工数]], "", T_FY27[[#This Row],[FY27工数]]-T_FY27[[#This Row],[FY26工数]]) | M40: 9
...

Sheet FY26工数
A1: Eng. | B1: 大カテゴリ | C1: 中カテゴリ | D1: タスクID | E1: タスク名 | F1: (作業用)タスク結合名 | G1: 恒久工数 | H1: 一時工数 | I1: FY26工数 | J1: FY25工数 | K1: 増減 | L1: 実施月 | M1: 担当1 | N1: 担当2 | O1: 担当3 | P1: 見積根拠
A2: FFG | B2: ITGC | C2: WT | E2: 勘定系 | F2: =A2&B2&C2&E2 -> FFGITGCWT勘定系 | G2: 41 | I2: =SUM(G2:H2) -> 41
A3: FFG | B3: ITGC | C3: TOC | E3: 勘定系 | F3: =A3&B3&C3&E3 -> FFGITGCTOC勘定系 | G3: 45 | I3: =SUM(G3:H3) -> 45
A4: FFG | B4: ITGC | C4: RF | E4: 勘定系 | F4: =A4&B4&C4&E4 -> FFGITGCRF勘定系 | G4: 11 | I4: =SUM(G4:H4) -> 11
A5: FFG | B5: ITGC | C5: WT | E5: 勘定系・融資支援(MCインフラ束ね) | F5: =A5&B5&C5&E5 -> FFGITGCWT勘定系・融資支援(MCインフラ束ね) | G5: 10 | I5: =SUM(G5:H5) -> 10
A6: FFG | B6: ITGC | C6: TOC | E6: 勘定系・融資支援(MCインフラ束ね) | F6: =A6&B6&C6&E6 -> FFGITGCTOC勘定系・融資支援(MCインフラ束ね) | G6: 12 | I6: =SUM(G6:H6) -> 12
A7: FFG | B7: ITGC | C7: RF | E7: 勘定系・融資支援(MCインフラ束ね) | F7: =A7&B7&C7&E7 -> FFGITGCRF勘定系・融資支援(MCインフラ束ね) | G7: 4 | I7: =SUM(G7:H7) -> 4
A8: FFG | B8: ITGC | C8: WT | E8: 勘定系・融資支援(MO障害束ね) | F8: =A8&B8&C8&E8 -> FFGITGCWT勘定系・融資支援(MO障害束ね) | G8: 10 | I8: =SUM(G8:H8) -> 10
A9: FFG | B9: ITGC | C9: TOC | E9: 勘定系・融資支援(MO障害束ね) | F9: =A9&B9&C9&E9 -> FFGITGCTOC勘定系・融資支援(MO障害束ね) | G9: 12 | I9: =SUM(G9:H9) -> 12
A10: FFG | B10: ITGC | C10: RF | E10: 勘定系・融資支援(MO障害束ね) | F10: =A10&B10&C10&E10 -> FFGITGCRF勘定系・融資支援(MO障害束ね) | G10: 4 | I10: =SUM(G10:H10) -> 4
A11: FFG | B11: ITGC | C11: WT | E11: 融資支援 | F11: =A11&B11&C11&E11 -> FFGITGCWT融資支援 | G11: 33 | I11: =SUM(G11:H11) -> 33
A12: FFG | B12: ITGC | C12: TOC | E12: 融資支援 | F12: =A12&B12&C12&E12 -> FFGITGCTOC融資支援 | G12: 45 | I12: =SUM(G12:H12) -> 45
A13: FFG | B13: ITGC | C13: RF | E13: 融資支援 | F13: =A13&B13&C13&E13 -> FFGITGCRF融資支援 | G13: 6 | I13: =SUM(G13:H13) -> 6
... A153: FFG | B153: 共通工数 | C153: その他 | E153: CIOディスカッション（ディスカッション資料・議事録）＊ | F153: =A153&B153&C153&E153 -> FFG共通工数その他CIOディスカッション（ディスカッション資料・議事録）＊ | G153: 8 | I153: =SUM(G153:H153) -> 8
